{
  "cells": [
    {
      "cell_type": "code",
      "execution_count": 1,
      "metadata": {
        "id": "VjYy0F2gZIPR",
        "outputId": "885856a1-ab8c-4b3a-d0d3-5f5d271d158d",
        "colab": {
          "base_uri": "https://localhost:8080/"
        }
      },
      "outputs": [
        {
          "output_type": "stream",
          "name": "stdout",
          "text": [
            "Collecting pygit2==1.15.1\n",
            "  Downloading pygit2-1.15.1-cp310-cp310-manylinux_2_17_x86_64.manylinux2014_x86_64.whl.metadata (3.3 kB)\n",
            "Requirement already satisfied: cffi>=1.16.0 in /usr/local/lib/python3.10/dist-packages (from pygit2==1.15.1) (1.17.1)\n",
            "Requirement already satisfied: pycparser in /usr/local/lib/python3.10/dist-packages (from cffi>=1.16.0->pygit2==1.15.1) (2.22)\n",
            "Downloading pygit2-1.15.1-cp310-cp310-manylinux_2_17_x86_64.manylinux2014_x86_64.whl (5.1 MB)\n",
            "\u001b[?25l   \u001b[90m━━━━━━━━━━━━━━━━━━━━━━━━━━━━━━━━━━━━━━━━\u001b[0m \u001b[32m0.0/5.1 MB\u001b[0m \u001b[31m?\u001b[0m eta \u001b[36m-:--:--\u001b[0m\r\u001b[2K   \u001b[91m━━━━━━━━━━━━━━━━━━━\u001b[0m\u001b[91m╸\u001b[0m\u001b[90m━━━━━━━━━━━━━━━━━━━━\u001b[0m \u001b[32m2.5/5.1 MB\u001b[0m \u001b[31m74.0 MB/s\u001b[0m eta \u001b[36m0:00:01\u001b[0m\r\u001b[2K   \u001b[91m━━━━━━━━━━━━━━━━━━━━━━━━━━━━━━━━━━━━━━━\u001b[0m\u001b[91m╸\u001b[0m \u001b[32m5.1/5.1 MB\u001b[0m \u001b[31m88.6 MB/s\u001b[0m eta \u001b[36m0:00:01\u001b[0m\r\u001b[2K   \u001b[90m━━━━━━━━━━━━━━━━━━━━━━━━━━━━━━━━━━━━━━━━\u001b[0m \u001b[32m5.1/5.1 MB\u001b[0m \u001b[31m59.9 MB/s\u001b[0m eta \u001b[36m0:00:00\u001b[0m\n",
            "\u001b[?25hTraceback (most recent call last):\n",
            "  File \"/usr/local/lib/python3.10/dist-packages/pip/_vendor/pkg_resources/__init__.py\", line 3070, in _dep_map\n",
            "    return self.__dep_map\n",
            "  File \"/usr/local/lib/python3.10/dist-packages/pip/_vendor/pkg_resources/__init__.py\", line 2863, in __getattr__\n",
            "    raise AttributeError(attr)\n",
            "AttributeError: _DistInfoDistribution__dep_map\n",
            "\n",
            "During handling of the above exception, another exception occurred:\n",
            "\n",
            "Traceback (most recent call last):\n",
            "  File \"/usr/local/lib/python3.10/dist-packages/pip/_internal/cli/base_command.py\", line 179, in exc_logging_wrapper\n",
            "    status = run_func(*args)\n",
            "  File \"/usr/local/lib/python3.10/dist-packages/pip/_internal/cli/req_command.py\", line 67, in wrapper\n",
            "    return func(self, options, args)\n",
            "  File \"/usr/local/lib/python3.10/dist-packages/pip/_internal/commands/install.py\", line 447, in run\n",
            "    conflicts = self._determine_conflicts(to_install)\n",
            "  File \"/usr/local/lib/python3.10/dist-packages/pip/_internal/commands/install.py\", line 578, in _determine_conflicts\n",
            "    return check_install_conflicts(to_install)\n",
            "  File \"/usr/local/lib/python3.10/dist-packages/pip/_internal/operations/check.py\", line 101, in check_install_conflicts\n",
            "    package_set, _ = create_package_set_from_installed()\n",
            "  File \"/usr/local/lib/python3.10/dist-packages/pip/_internal/operations/check.py\", line 42, in create_package_set_from_installed\n",
            "    dependencies = list(dist.iter_dependencies())\n",
            "  File \"/usr/local/lib/python3.10/dist-packages/pip/_internal/metadata/pkg_resources.py\", line 247, in iter_dependencies\n",
            "    return self._dist.requires(extras)\n",
            "  File \"/usr/local/lib/python3.10/dist-packages/pip/_vendor/pkg_resources/__init__.py\", line 2786, in requires\n",
            "    dm = self._dep_map\n",
            "  File \"/usr/local/lib/python3.10/dist-packages/pip/_vendor/pkg_resources/__init__.py\", line 3072, in _dep_map\n",
            "    self.__dep_map = self._compute_dependencies()\n",
            "  File \"/usr/local/lib/python3.10/dist-packages/pip/_vendor/pkg_resources/__init__.py\", line 3082, in _compute_dependencies\n",
            "    reqs.extend(parse_requirements(req))\n",
            "  File \"/usr/local/lib/python3.10/dist-packages/pip/_vendor/pkg_resources/__init__.py\", line 3140, in __init__\n",
            "    self.extras = tuple(map(safe_extra, self.extras))\n",
            "KeyboardInterrupt\n",
            "\n",
            "During handling of the above exception, another exception occurred:\n",
            "\n",
            "Traceback (most recent call last):\n",
            "  File \"/usr/lib/python3.10/logging/__init__.py\", line 1732, in isEnabledFor\n",
            "    return self._cache[level]\n",
            "KeyError: 50\n",
            "\n",
            "During handling of the above exception, another exception occurred:\n",
            "\n",
            "Traceback (most recent call last):\n",
            "  File \"/usr/local/bin/pip3\", line 8, in <module>\n",
            "    sys.exit(main())\n",
            "  File \"/usr/local/lib/python3.10/dist-packages/pip/_internal/cli/main.py\", line 80, in main\n",
            "    return command.main(cmd_args)\n",
            "  File \"/usr/local/lib/python3.10/dist-packages/pip/_internal/cli/base_command.py\", line 100, in main\n",
            "    return self._main(args)\n",
            "  File \"/usr/local/lib/python3.10/dist-packages/pip/_internal/cli/base_command.py\", line 232, in _main\n",
            "    return run(options, args)\n",
            "  File \"/usr/local/lib/python3.10/dist-packages/pip/_internal/cli/base_command.py\", line 215, in exc_logging_wrapper\n",
            "    logger.critical(\"Operation cancelled by user\")\n",
            "  File \"/usr/lib/python3.10/logging/__init__.py\", line 1523, in critical\n",
            "    if self.isEnabledFor(CRITICAL):\n",
            "  File \"/usr/lib/python3.10/logging/__init__.py\", line 1734, in isEnabledFor\n",
            "    _acquireLock()\n",
            "KeyboardInterrupt\n",
            "^C\n",
            "/content\n",
            "Cloning into 'Fooocus'...\n",
            "remote: Enumerating objects: 6718, done.\u001b[K\n",
            "^C\n",
            "[Errno 2] No such file or directory: '/content/Fooocus'\n",
            "/content\n",
            "python3: can't open file '/content/entry_with_update.py': [Errno 2] No such file or directory\n"
          ]
        }
      ],
      "source": [
        "!pip install pygit2==1.15.1\n",
        "%cd /content\n",
        "!git clone https://github.com/lllyasviel/Fooocus.git\n",
        "%cd /content/Fooocus\n",
        "!python entry_with_update.py --share --always-high-vram\n"
      ]
    }
  ],
  "metadata": {
    "accelerator": "GPU",
    "colab": {
      "gpuType": "T4",
      "provenance": []
    },
    "kernelspec": {
      "display_name": "Python 3",
      "name": "python3"
    },
    "language_info": {
      "name": "python"
    }
  },
  "nbformat": 4,
  "nbformat_minor": 0
}